Workbook

Sheet 🏠 Início
A2: AVALIAÇÃO DE PROPOSTAS COMERCIAIS DE SISTEMA SOLAR
A3: MÉTODO BUY-SIDE SOLUÇÕES
A4: Bem-vindo(a)! Compare até 6 propostas de empresas de energia solar e descubra as 2 finalistas
A5: 📖 COMO USAR
A6: 1️⃣ Para cada vendedor que aparecer, preencha os 3 formulários da empresa dele
A7: 2️⃣ Os dados dos formulários alimentam automaticamente as tabelas comparativas
A8: 3️⃣ Pontue cada item nas tabelas comparativas (Empresas e Tecnologia)
A9: 4️⃣ Na aba Pontuação Geral, você escolhe as 2 propostas finalistas para a última rodada de negociação 🏆 🏆
A11: 📍 POR ONDE COMEÇAR
B13: AÇÃO 1 | H13: AÇÃO 2 | N13: AÇÃO 3
B14: 🏢 | H14: ⚙️ | N14: 💰
B15: Avaliação da Empresa | H15: Proposta Técnica | N15: Viabilidade Financeira
B16: Dados da empresa, garantias, | H16: Sistema FV, módulo, inversor, | N16: Conta de energia, preços, prazo,
B17: vendedor e documentação | H17: reputação do fabricante | N17: rentabilidade
B18: =HYPERLINK("#'Form. Empresa'!A1","✏️ Preencher formulário") -> ✏️ Preencher formulário | H18: =HYPERLINK("#'Form. Tecnológico'!A1","✏️ Preencher formulário") -> ✏️ Preencher formulário | N18: =HYPERLINK("#'Form. Financeiro'!A1","✏️ Preencher formulário") -> ✏️ Preencher formulário
B19: =HYPERLINK("#'Avaliação Empresas'!A1","📊 Ver tabela comparativa") -> 📊 Ver tabela comparativa | H19: =HYPERLINK("#'Avaliação Tecnológica'!A1","📊 Ver tabela comparativa") -> 📊 Ver tabela comparativa | N19: =HYPERLINK("#'Viabilidade Financeira'!A1","📊 Ver tabela comparativa") -> 📊 Ver tabela comparativa
A21: 🏆 RESULTADO FINAL
A22: =IF(COUNTA('Form. Empresa'!C9,'Form. Empresa'!C29,'Form. Empresa'!C49,'Form. Empresa'!C69,'Form. Empresa'!C89,'Form. Empresa'!C109)=0,"⏳ Aguardando o preenchimento dos formulários das empresas",IF(COUNTIF('Pontuação Geral'!B14:G14,"*Finalista*")<2,"📊 Pontue as propostas e escolha 2 finalistas na aba Pontuação Geral","✅ Finalistas: "&LEFT(IF(ISNUMBER(SEARCH("Finalista",'Pontuação Geral'!B14)),'Pontuação Geral'!B5&" + ","")&IF(ISNUMBER(SEARCH("Finalista",'Pontuação Geral'!C14)),'Pontuação Geral'!C5&" + ","")&IF(ISNUMBER(SEARCH("Finalista",'Pontuação Geral'!D14)),'Pontuação Geral'!D5&" + ","")&IF(ISNUMBER(SEARCH("Finalista",'Pontuação Geral'!E14)),'Pontuação Geral'!E5&" + ","")&IF(ISNUMBER(SEARCH("Finalista",'Pontuação Geral'!F14)),'Pontuação Geral'!F5&" + ","")&IF(ISNUMBER(SEARCH("Finalista",'Pontuação Geral'!G14)),'Pontuação Geral'!G5&" + ",""),LEN(IF(ISNUMBER(SEARCH("Finalista",'Pontuação Geral'!B14)),'Pontuação Geral'!B5&" + ","")&IF(ISNUMBER(SEARCH("Finalista",'Pontuação Geral'!C14)),'Pontuação Geral'!C5&" + ","")&IF(ISNUMBER(SEARCH("Finalista",'Pontuação Geral'!D14)),'Pontuação Geral'!D5&" + ","")&IF(ISNUMBER(SEARCH("Finalista",'Pontuação Geral'!E14)),'Pontuação Geral'!E5&" + ","")&IF(ISNUMBER(SEARCH("Finalista",'Pontuação Geral'!F14)),'Pontuação Geral'!F5&" + ","")&IF(ISNUMBER(SEARCH("Finalista",'Pontuação Geral'!G14)),'Pontuação Geral'!G5&" + ",""))-7))) -> ✅ Finalistas: RENOVA + SOLI SOLAR
A23: =HYPERLINK("#'Pontuação Geral'!A1","🏆 Ver detalhes do resultado") -> 🏆 Ver detalhes do resultado
A25: © 2026 Solar Buy-Side. Todos os direitos reservados.
A26: Material protegido pela Lei nº 9.610/98 (Lei de Direitos Autorais). A reprodução, distribuição, modificação ou uso comercial — total ou parcial — é proibida sem autorização expressa do autor.

Sheet Form. Empresa
B2: 🏢 PASSO 1 de 3 — AVALIAÇÃO DA EMPRESA DE SOLAR
B3: ⏰ PREENCHA NA HORA — enquanto o vendedor apresenta a proposta. O nome digitado aqui propaga nos outros 2 formulários.
B5: 🏠 Voltar ao Início | C5: Próximo: ⚙️ PASSO 2 →
D7: PULAR PARA EMPRESA ↓
B8: 📋 EMPRESA 1 | D8: 1 | E8: 2 | F8: 3 | G8: 4 | H8: 5 | I8: 6
B9: ✏️ Nome da empresa | C9: RENOVA
B10: 🏢 A EMPRESA
B11: Atuação no ramo solar desde (ano) | C11: 2021
B12: Ano de abertura da empresa | C12: 2020
B13: Registro CREA engenharia elétrica (sim/não) | C13: Sim
B14: Colação de Grau do Engenheiro responsável (ano) | C14: 2004
B15: Quantidade de SFV instalado (aproximadamente) | C15: + de 100
B16: Instalações são realizadas por funcionário próprio (sim/não) | C16: Não
B17: ✅ COMPROMETIMENTO DA EMPRESA
B18: Prazo máximo de instalação do sistema solar (dias ou semanas) | C18: 60 dias
B19: Garantia contra defeito de projeto e execução (anos) | C19: 3 anos
B20: 🛠️ ASSISTÊNCIA TÉCNICA E MANUTENÇÃO
B21: Existência de serviço de manutenção e assistência (sim/não) | C21: Sim
B22: Prazo de assistência técnica (dias) | C22: 6 dias
B23: 📄 ENTREGA DE DOCUMENTOS TÉCNICOS
B24: Entregue cópia do memorial descritivo e diagrama unifilar (sim/não) | C24: Sim
B25: 🤝 AVALIAÇÃO DO VENDEDOR PELO COMPRADOR
B26: Sentiu empatia e confiança com o vendedor (sim/não) | C26: Sim
B27: Reclame Aqui: Nota Média dos últimos 12 meses (ex: 5,5/10) | D27: PULAR PARA EMPRESA ↓
B28: 📋 EMPRESA 2 | D28: 1 | E28: 2 | F28: 3 | G28: 4 | H28: 5 | I28: 6
B29: ✏️ Nome da empresa | C29: SOLI SOLAR
B30: 🏢 A EMPRESA
B31: Atuação no ramo solar desde (ano)
B32: Ano de abertura da empresa
B33: Registro CREA engenharia elétrica (sim/não)
B34: Colação de Grau do Engenheiro responsável (ano)
B35: Quantidade de SFV instalado (aproximadamente)
B36: Instalações são realizadas por funcionário próprio (sim/não)
B37: ✅ COMPROMETIMENTO DA EMPRESA
B38: Prazo máximo de instalação do sistema solar (dias ou semanas)
B39: Garantia contra defeito de projeto e execução (anos)
B40: 🛠️ ASSISTÊNCIA TÉCNICA E MANUTENÇÃO
B41: Existência de serviço de manutenção e assistência (sim/não)
... B46: Sentiu empatia e confiança com o vendedor (sim/não)
B47: Reclame Aqui: Nota Média dos últimos 12 meses (ex: 5,5/10) | D47: PULAR PARA EMPRESA ↓
...

Sheet Avaliação Empresas
A1: 📊 Tabela 1 — Avaliação das Empresas (com pontuação)
A2: ← Voltar ao Form. Empresa | E2: 🏠 Início | I2: Próximo: Form. Tecnológico →
A4: Legenda:
A5: Item | B5: =IF('Form. Empresa'!C9="","1",'Form. Empresa'!C9) -> RENOVA | C5: P | D5: =IF('Form. Empresa'!C29="","2",'Form. Empresa'!C29) -> SOLI SOLAR | E5: P | F5: =IF('Form. Empresa'!C49="","3",'Form. Empresa'!C49) -> ENERGIA SGE | G5: P | H5: =IF('Form. Empresa'!C69="","4",'Form. Empresa'!C69) -> TAP SOLAR | I5: P | J5: =IF('Form. Empresa'!C89="","5",'Form. Empresa'!C89) -> FOTOVOLTA EXPRESS | K5: P | L5: =IF('Form. Empresa'!C109="","6",'Form. Empresa'!C109) -> SELF SOLAR | M5: P | N5: Avaliar?
A6: A empresa de solar
A7: Atuação no ramo solar | B7: =IF('Form. Empresa'!C11="","",'Form. Empresa'!C11) -> 2021 | C7: 7 | D7: =IF('Form. Empresa'!C31="","",'Form. Empresa'!C31) | E7: 8 | F7: =IF('Form. Empresa'!C51="","",'Form. Empresa'!C51) | G7: 3 | H7: =IF('Form. Empresa'!C71="","",'Form. Empresa'!C71) | I7: 4 | J7: =IF('Form. Empresa'!C91="","",'Form. Empresa'!C91) | K7: 5 | L7: =IF('Form. Empresa'!C111="","",'Form. Empresa'!C111) | M7: 3 | N7: Sim
A8: Ano de abertura da empresa | B8: =IF('Form. Empresa'!C12="","",'Form. Empresa'!C12) -> 2020 | C8: 4 | D8: =IF('Form. Empresa'!C32="","",'Form. Empresa'!C32) | E8: 9 | F8: =IF('Form. Empresa'!C52="","",'Form. Empresa'!C52) | G8: 4 | H8: =IF('Form. Empresa'!C72="","",'Form. Empresa'!C72) | I8: 5 | J8: =IF('Form. Empresa'!C92="","",'Form. Empresa'!C92) | K8: 6 | L8: =IF('Form. Empresa'!C112="","",'Form. Empresa'!C112) | M8: 3 | N8: Sim
A9: Registro CREA engenharia elétrica | B9: =IF('Form. Empresa'!C13="","",'Form. Empresa'!C13) -> Sim | C9: 10 | D9: =IF('Form. Empresa'!C33="","",'Form. Empresa'!C33) | E9: 8 | F9: =IF('Form. Empresa'!C53="","",'Form. Empresa'!C53) | G9: 1 | H9: =IF('Form. Empresa'!C73="","",'Form. Empresa'!C73) | I9: 3 | J9: =IF('Form. Empresa'!C93="","",'Form. Empresa'!C93) | K9: 5 | L9: =IF('Form. Empresa'!C113="","",'Form. Empresa'!C113) | M9: 3 | N9: Sim
A10: Ano de colação de grau do engenheiro | B10: =IF('Form. Empresa'!C14="","",'Form. Empresa'!C14) -> 2004 | C10: 9 | D10: =IF('Form. Empresa'!C34="","",'Form. Empresa'!C34) | E10: 7 | F10: =IF('Form. Empresa'!C54="","",'Form. Empresa'!C54) | G10: 1 | H10: =IF('Form. Empresa'!C74="","",'Form. Empresa'!C74) | I10: 3 | J10: =IF('Form. Empresa'!C94="","",'Form. Empresa'!C94) | K10: 7 | L10: =IF('Form. Empresa'!C114="","",'Form. Empresa'!C114) | M10: 3 | N10: Sim
A11: Quantidade de SFV instalado | B11: =IF('Form. Empresa'!C15="","",'Form. Empresa'!C15) -> + de 100 | C11: 8 | D11: =IF('Form. Empresa'!C35="","",'Form. Empresa'!C35) | E11: 8 | F11: =IF('Form. Empresa'!C55="","",'Form. Empresa'!C55) | G11: 1 | H11: =IF('Form. Empresa'!C75="","",'Form. Empresa'!C75) | I11: 4 | J11: =IF('Form. Empresa'!C95="","",'Form. Empresa'!C95) | K11: 7 | L11: =IF('Form. Empresa'!C115="","",'Form. Empresa'!C115) | M11: 3 | N11: Sim
A12: Instalações são feitas por funcionário próprio | B12: =IF('Form. Empresa'!C16="","",'Form. Empresa'!C16) -> Não | C12: 5 | D12: =IF('Form. Empresa'!C36="","",'Form. Empresa'!C36) | E12: 8 | F12: =IF('Form. Empresa'!C56="","",'Form. Empresa'!C56) | G12: 4 | H12: =IF('Form. Empresa'!C76="","",'Form. Empresa'!C76) | I12: 4 | J12: =IF('Form. Empresa'!C96="","",'Form. Empresa'!C96) | K12: 7 | L12: =IF('Form. Empresa'!C116="","",'Form. Empresa'!C116) | M12: 3 | N12: Sim
A13: Comprometimento da empresa
A14: Prazo de instalação do sistema solar | B14: =IF('Form. Empresa'!C18="","",'Form. Empresa'!C18) -> 60 dias | C14: 4 | D14: =IF('Form. Empresa'!C38="","",'Form. Empresa'!C38) | E14: 7 | F14: =IF('Form. Empresa'!C58="","",'Form. Empresa'!C58) | G14: 3 | H14: =IF('Form. Empresa'!C78="","",'Form. Empresa'!C78) | I14: 3 | J14: =IF('Form. Empresa'!C98="","",'Form. Empresa'!C98) | K14: 7 | L14: =IF('Form. Empresa'!C118="","",'Form. Empresa'!C118) | M14: 3 | N14: Sim
A15: Garantia contra defeito de projeto e execução do sistema solar (prazo) | B15: =IF('Form. Empresa'!C19="","",'Form. Empresa'!C19) -> 3 anos | C15: 6 | D15: =IF('Form. Empresa'!C39="","",'Form. Empresa'!C39) | E15: 8 | F15: =IF('Form. Empresa'!C59="","",'Form. Empresa'!C59) | G15: 2 | H15: =IF('Form. Empresa'!C79="","",'Form. Empresa'!C79) | I15: 4 | J15: =IF('Form. Empresa'!C99="","",'Form. Empresa'!C99) | K15: 5 | L15: =IF('Form. Empresa'!C119="","",'Form. Empresa'!C119) | M15: 3 | N15: Sim
A16: Assistência técnica & manutenção
A17: Apresentou prova de serviço de manutenção e assistência | B17: =IF('Form. Empresa'!C21="","",'Form. Empresa'!C21) -> Sim | C17: 5 | D17: =IF('Form. Empresa'!C41="","",'Form. Empresa'!C41) | E17: 7 | F17: =IF('Form. Empresa'!C61="","",'Form. Empresa'!C61) | G17: 1 | H17: =IF('Form. Empresa'!C81="","",'Form. Empresa'!C81) | I17: 4 | J17: =IF('Form. Empresa'!C101="","",'Form. Empresa'!C101) | K17: 7 | L17: =IF('Form. Empresa'!C121="","",'Form. Empresa'!C121) | M17: 3 | N17: Sim
A18: Prazo de assistência técnica (dias) | B18: =IF('Form. Empresa'!C22="","",'Form. Empresa'!C22) -> 6 dias | C18: 7 | D18: =IF('Form. Empresa'!C42="","",'Form. Empresa'!C42) | E18: 7 | F18: =IF('Form. Empresa'!C62="","",'Form. Empresa'!C62) | G18: 1 | H18: =IF('Form. Empresa'!C82="","",'Form. Empresa'!C82) | I18: 3 | J18: =IF('Form. Empresa'!C102="","",'Form. Empresa'!C102) | K18: 5 | L18: =IF('Form. Empresa'!C122="","",'Form. Empresa'!C122) | M18: 4 | N18: Sim
A19: Final da instalação
A20: Entrega cópia do memorial descritivo do projeto e diagrama unifilar | B20: =IF('Form. Empresa'!C24="","",'Form. Empresa'!C24) -> Sim | C20: 8 | D20: =IF('Form. Empresa'!C44="","",'Form. Empresa'!C44) | E20: 7 | F20: =IF('Form. Empresa'!C64="","",'Form. Empresa'!C64) | G20: 1 | H20: =IF('Form. Empresa'!C84="","",'Form. Empresa'!C84) | I20: 4 | J20: =IF('Form. Empresa'!C104="","",'Form. Empresa'!C104) | K20: 5 | L20: =IF('Form. Empresa'!C124="","",'Form. Empresa'!C124) | M20: 5 | N20: Sim
A21: Avaliação do vendedor pelo comprador
A22: Sinta empatia com o vendedor | B22: =IF('Form. Empresa'!C26="","",'Form. Empresa'!C26) -> Sim | C22: 8 | D22: =IF('Form. Empresa'!C46="","",'Form. Empresa'!C46) | E22: 8 | F22: =IF('Form. Empresa'!C66="","",'Form. Empresa'!C66) | G22: 4 | H22: =IF('Form. Empresa'!C86="","",'Form. Empresa'!C86) | I22: 5 | J22: =IF('Form. Empresa'!C106="","",'Form. Empresa'!C106) | K22: 6 | L22: =IF('Form. Empresa'!C126="","",'Form. Empresa'!C126) | M22: 5 | N22: Sim
A23: Reclame Aqui: Nota Média dos últimos 12 meses | B23: =IF('Form. Empresa'!C27="","",'Form. Empresa'!C27) | C23: 0 | D23: =IF('Form. Empresa'!C47="","",'Form. Empresa'!C47) | E23: 0 | F23: =IF('Form. Empresa'!C67="","",'Form. Empresa'!C67) | G23: 0 | H23: =IF('Form. Empresa'!C87="","",'Form. Empresa'!C87) | I23: 0 | J23: =IF('Form. Empresa'!C107="","",'Form. Empresa'!C107) | K23: 0 | L23: =IF('Form. Empresa'!C127="","",'Form. Empresa'!C127) | M23: 0 | N23: Sim
A24: TOTAL DA PONTUAÇÃO | C24: =IF($N7="Sim",IFERROR(N(C7),0),0)+IF($N8="Sim",IFERROR(N(C8),0),0)+IF($N9="Sim",IFERROR(N(C9),0),0)+IF($N10="Sim",IFERROR(N(C10),0),0)+IF($N11="Sim",IFERROR(N(C11),0),0)+IF($N12="Sim",IFERROR(N(C12),0),0)+IF($N14="Sim",IFERROR(N(C14),0),0)+IF($N15="Sim",IFERROR(N(C15),0),0)+IF($N17="Sim",IFERROR(N(C17),0),0)+IF($N18="Sim",IFERROR(N(C18),0),0)+IF($N20="Sim",IFERROR(N(C20),0),0)+IF($N22="Sim",IFERROR(N(C22),0),0)+IF($N23="Sim",IFERROR(N(C23),0),0) -> 81 | E24: =IF($N7="Sim",IFERROR(N(E7),0),0)+IF($N8="Sim",IFERROR(N(E8),0),0)+IF($N9="Sim",IFERROR(N(E9),0),0)+IF($N10="Sim",IFERROR(N(E10),0),0)+IF($N11="Sim",IFERROR(N(E11),0),0)+IF($N12="Sim",IFERROR(N(E12),0),0)+IF($N14="Sim",IFERROR(N(E14),0),0)+IF($N15="Sim",IFERROR(N(E15),0),0)+IF($N17="Sim",IFERROR(N(E17),0),0)+IF($N18="Sim",IFERROR(N(E18),0),0)+IF($N20="Sim",IFERROR(N(E20),0),0)+IF($N22="Sim",IFERROR(N(E22),0),0)+IF($N23="Sim",IFERROR(N(E23),0),0) -> 92 | G24: =IF($N7="Sim",IFERROR(N(G7),0),0)+IF($N8="Sim",IFERROR(N(G8),0),0)+IF($N9="Sim",IFERROR(N(G9),0),0)+IF($N10="Sim",IFERROR(N(G10),0),0)+IF($N11="Sim",IFERROR(N(G11),0),0)+IF($N12="Sim",IFERROR(N(G12),0),0)+IF($N14="Sim",IFERROR(N(G14),0),0)+IF($N15="Sim",IFERROR(N(G15),0),0)+IF($N17="Sim",IFERROR(N(G17),0),0)+IF($N18="Sim",IFERROR(N(G18),0),0)+IF($N20="Sim",IFERROR(N(G20),0),0)+IF($N22="Sim",IFERROR(N(G22),0),0)+IF($N23="Sim",IFERROR(N(G23),0),0) -> 26 | I24: =IF($N7="Sim",IFERROR(N(I7),0),0)+IF($N8="Sim",IFERROR(N(I8),0),0)+IF($N9="Sim",IFERROR(N(I9),0),0)+IF($N10="Sim",IFERROR(N(I10),0),0)+IF($N11="Sim",IFERROR(N(I11),0),0)+IF($N12="Sim",IFERROR(N(I12),0),0)+IF($N14="Sim",IFERROR(N(I14),0),0)+IF($N15="Sim",IFERROR(N(I15),0),0)+IF($N17="Sim",IFERROR(N(I17),0),0)+IF($N18="Sim",IFERROR(N(I18),0),0)+IF($N20="Sim",IFERROR(N(I20),0),0)+IF($N22="Sim",IFERROR(N(I22),0),0)+IF($N23="Sim",IFERROR(N(I23),0),0) -> 46 | K24: =IF($N7="Sim",IFERROR(N(K7),0),0)+IF($N8="Sim",IFERROR(N(K8),0),0)+IF($N9="Sim",IFERROR(N(K9),0),0)+IF($N10="Sim",IFERROR(N(K10),0),0)+IF($N11="Sim",IFERROR(N(K11),0),0)+IF($N12="Sim",IFERROR(N(K12),0),0)+IF($N14="Sim",IFERROR(N(K14),0),0)+IF($N15="Sim",IFERROR(N(K15),0),0)+IF($N17="Sim",IFERROR(N(K17),0),0)+IF($N18="Sim",IFERROR(N(K18),0),0)+IF($N20="Sim",IFERROR(N(K20),0),0)+IF($N22="Sim",IFERROR(N(K22),0),0)+IF($N23="Sim",IFERROR(N(K23),0),0) -> 72 | M24: =IF($N7="Sim",IFERROR(N(M7),0),0)+IF($N8="Sim",IFERROR(N(M8),0),0)+IF($N9="Sim",IFERROR(N(M9),0),0)+IF($N10="Sim",IFERROR(N(M10),0),0)+IF($N11="Sim",IFERROR(N(M11),0),0)+IF($N12="Sim",IFERROR(N(M12),0),0)+IF($N14="Sim",IFERROR(N(M14),0),0)+IF($N15="Sim",IFERROR(N(M15),0),0)+IF($N17="Sim",IFERROR(N(M17),0),0)+IF($N18="Sim",IFERROR(N(M18),0),0)+IF($N20="Sim",IFERROR(N(M20),0),0)+IF($N22="Sim",IFERROR(N(M22),0),0)+IF($N23="Sim",IFERROR(N(M23),0),0) -> 41
A25: Itens avaliados (de 13) | C25: =COUNTIF($N$7:$N$23,"Sim") -> 13 | E25: =COUNTIF($N$7:$N$23,"Sim") -> 13 | G25: =COUNTIF($N$7:$N$23,"Sim") -> 13 | I25: =COUNTIF($N$7:$N$23,"Sim") -> 13 | K25: =COUNTIF($N$7:$N$23,"Sim") -> 13 | M25: =COUNTIF($N$7:$N$23,"Sim") -> 13
A26: Pontuação máxima possível | C26: =COUNTIF($N$7:$N$23,"Sim")*10 -> 130 | E26: =COUNTIF($N$7:$N$23,"Sim")*10 -> 130 | G26: =COUNTIF($N$7:$N$23,"Sim")*10 -> 130 | I26: =COUNTIF($N$7:$N$23,"Sim")*10 -> 130 | K26: =COUNTIF($N$7:$N$23,"Sim")*10 -> 130 | M26: =COUNTIF($N$7:$N$23,"Sim")*10 -> 130
A28: © 2026 Buy-Side Soluções. Todos os direitos reservados.
A29: Material protegido pela Lei nº 9.610/98 (Lei de Direitos Autorais). A reprodução, distribuição, modificação ou uso comercial — total ou parcial — é proibida sem autorização expressa do autor.

Sheet Form. Tecnológico
B2: ⚙️ PASSO 2 de 3 — AVALIAÇÃO DA PROPOSTA TÉCNICA
B3: 🏠 PREENCHA EM CASA — depois de receber a proposta. Pode consultar Reclame Aqui, comparar specs, analisar com calma.
B5: ← Anterior: 🏢 PASSO 1 | C5: Próximo: 💰 PASSO 3 →
D7: PULAR PARA EMPRESA ↓
B8: ⚙️ EMPRESA 1 | D8: 1 | E8: 2 | F8: 3 | G8: 4 | H8: 5 | I8: 6
B9: 📌 Empresa (preenchida automaticamente) | C9: ='Form. Empresa'!C9 -> RENOVA
B10: ☀️ SISTEMA SOLAR FOTOVOLTAICO
B11: Potência do sistema (kilo Watt pico) | C11: 6,435 kWp
B12: ⚡ ESTIMATIVA DE GERAÇÃO DE ENERGIA
B13: Geração mensal média (kWh) | C13: 727 kWh/mês
B14: Geração anual (kWh) | C14: 8.732 kWh/ano
B15: 🔆 MÓDULO FOTOVOLTAICO
B16: Marca | C16: HANERSUN
B17: Modelo | C17: HN18N-72H
B18: Potência do módulo (watts) | C18: 585 W
B19: Peso (kg) | C19: 28,5 kg
B20: Eficiência de conversão de radiação (%) | C20: 22,6%
B21: Eficiência aos 25 ou 30 anos | C21: 85,0% (25 anos)
B22: Garantia contra defeito (anos) | C22: 12 anos
B23: Garantia de eficiência (25 ou 30 anos) | C23: 25 anos
B24: Número de módulos | C24: 11
B25: 🔌 INVERSOR DE CORRENTE
B26: Marca | C26: GOODWE
B27: Modelo | C27: GW5000 DNS 30
B28: Potência (kW) | C28: 5 KW
B29: Garantia contra defeito (anos) | C29: 12 anos
B30: Número de inversores | C30: 1
B31: 📐 SOBRECARGA DO INVERSOR (comum entre 1,25 a 1,35)
B32: Sobrecarga calculada (kWp / kW) | C32: 1,28 ou 28%
B33: 🔍 RECLAME AQUI — Reputação dos últimos 12 meses
B34: Distribuidora de sistema solar fotovoltaico | C34: 8,4/10 - Reputação Ótima
B35: Fabricante de módulo fotovoltaico | C35: Hanersun - sem avaliação
B36: Fabricante de inversor de corrente | C36: Growatt - 7,6 - Reputação Boa
B37: ✅ CONFIABILIDADE DOS FABRICANTES E DISTRIBUIDORAS (sim/não/não sei)
B38: Inversor de corrente | C38: Sim
B39: Módulo fotovoltaico | C39: Não sei
B40: Distribuidora de equipamento | C40: Sim
D41: PULAR PARA EMPRESA ↓
B42: ⚙️ EMPRESA 2 | D42: 1 | E42: 2 | F42: 3 | G42: 4 | H42: 5 | I42: 6
B43: 📌 Empresa (preenchida automaticamente) | C43: ='Form. Empresa'!C29 -> SOLI SOLAR
...

Sheet Avaliação Tecnológica
A1: 📊 Tabela 2 — Avaliação Tecnológica (com pontuação)
A2: ← Voltar ao Form. Tecnológico | E2: 🏠 Início | I2: Próximo: Form. Financeiro →
A4: Legenda:
A5: Item | B5: =IF('Form. Empresa'!C9="","1",'Form. Empresa'!C9) -> RENOVA | C5: P | D5: =IF('Form. Empresa'!C29="","2",'Form. Empresa'!C29) -> SOLI SOLAR | E5: P | F5: =IF('Form. Empresa'!C49="","3",'Form. Empresa'!C49) -> ENERGIA SGE | G5: P | H5: =IF('Form. Empresa'!C69="","4",'Form. Empresa'!C69) -> TAP SOLAR | I5: P | J5: =IF('Form. Empresa'!C89="","5",'Form. Empresa'!C89) -> FOTOVOLTA EXPRESS | K5: P | L5: =IF('Form. Empresa'!C109="","6",'Form. Empresa'!C109) -> SELF SOLAR | M5: P | N5: Avaliar?
A6: Sistema solar fotovoltaico
A7: Potência do sistema (kWp - Kilo Watt pico) | B7: =IF('Form. Tecnológico'!C11="","",'Form. Tecnológico'!C11) -> 6,435 kWp | C7: 10 | D7: =IF('Form. Tecnológico'!C45="","",'Form. Tecnológico'!C45) | E7: 8 | F7: =IF('Form. Tecnológico'!C79="","",'Form. Tecnológico'!C79) | G7: 6 | H7: =IF('Form. Tecnológico'!C113="","",'Form. Tecnológico'!C113) | I7: 4 | J7: =IF('Form. Tecnológico'!C147="","",'Form. Tecnológico'!C147) | K7: 5 | L7: =IF('Form. Tecnológico'!C181="","",'Form. Tecnológico'!C181) | M7: 9 | N7: Sim
A8: Estimação de geração de energia
A9: Geração mensal média (kWh) | B9: =IF('Form. Tecnológico'!C13="","",'Form. Tecnológico'!C13) -> 727 kWh/mês | C9: 10 | D9: =IF('Form. Tecnológico'!C47="","",'Form. Tecnológico'!C47) | E9: 8 | F9: =IF('Form. Tecnológico'!C81="","",'Form. Tecnológico'!C81) | G9: 6 | H9: =IF('Form. Tecnológico'!C115="","",'Form. Tecnológico'!C115) | I9: 4 | J9: =IF('Form. Tecnológico'!C149="","",'Form. Tecnológico'!C149) | K9: 5 | L9: =IF('Form. Tecnológico'!C183="","",'Form. Tecnológico'!C183) | M9: 8 | N9: Sim
A10: Geração anual (kWh) | B10: =IF('Form. Tecnológico'!C14="","",'Form. Tecnológico'!C14) -> 8.732 kWh/ano | C10: 10 | D10: =IF('Form. Tecnológico'!C48="","",'Form. Tecnológico'!C48) | E10: 9 | F10: =IF('Form. Tecnológico'!C82="","",'Form. Tecnológico'!C82) | G10: 7 | H10: =IF('Form. Tecnológico'!C116="","",'Form. Tecnológico'!C116) | I10: 5 | J10: =IF('Form. Tecnológico'!C150="","",'Form. Tecnológico'!C150) | K10: 6 | L10: =IF('Form. Tecnológico'!C184="","",'Form. Tecnológico'!C184) | M10: 9 | N10: Sim
A11: Módulo fotovoltaico
A12: Marca | B12: =IF('Form. Tecnológico'!C16="","",'Form. Tecnológico'!C16) -> HANERSUN | D12: =IF('Form. Tecnológico'!C50="","",'Form. Tecnológico'!C50) | E12: 8 | F12: =IF('Form. Tecnológico'!C84="","",'Form. Tecnológico'!C84) | G12: 6 | H12: =IF('Form. Tecnológico'!C118="","",'Form. Tecnológico'!C118) | I12: 4 | J12: =IF('Form. Tecnológico'!C152="","",'Form. Tecnológico'!C152) | K12: 5 | L12: =IF('Form. Tecnológico'!C186="","",'Form. Tecnológico'!C186) | M12: 9 | N12: Sim
A13: Modelo | B13: =IF('Form. Tecnológico'!C17="","",'Form. Tecnológico'!C17) -> HN18N-72H | D13: =IF('Form. Tecnológico'!C51="","",'Form. Tecnológico'!C51) | E13: 9 | F13: =IF('Form. Tecnológico'!C85="","",'Form. Tecnológico'!C85) | G13: 7 | H13: =IF('Form. Tecnológico'!C119="","",'Form. Tecnológico'!C119) | I13: 9 | J13: =IF('Form. Tecnológico'!C153="","",'Form. Tecnológico'!C153) | K13: 5 | L13: =IF('Form. Tecnológico'!C187="","",'Form. Tecnológico'!C187) | M13: 9 | N13: Sim
A14: Potência módulo (watt) | B14: =IF('Form. Tecnológico'!C18="","",'Form. Tecnológico'!C18) -> 585 W | C14: 10 | D14: =IF('Form. Tecnológico'!A86="","",'Form. Tecnológico'!A86) | E14: 10 | F14: =IF('Form. Tecnológico'!C86="","",'Form. Tecnológico'!C86) | G14: 10 | H14: =IF('Form. Tecnológico'!C120="","",'Form. Tecnológico'!C120) | I14: 10 | J14: =IF('Form. Tecnológico'!C154="","",'Form. Tecnológico'!C154) | K14: 10 | L14: =IF('Form. Tecnológico'!C188="","",'Form. Tecnológico'!C188) | M14: 10 | N14: Sim
A15: Peso (kg) | B15: =IF('Form. Tecnológico'!C19="","",'Form. Tecnológico'!C19) -> 28,5 kg | C15: 10 | D15: =IF('Form. Tecnológico'!C53="","",'Form. Tecnológico'!C53) | E15: 10 | F15: =IF('Form. Tecnológico'!C87="","",'Form. Tecnológico'!C87) | G15: 10 | H15: =IF('Form. Tecnológico'!C121="","",'Form. Tecnológico'!C121) | I15: 10 | J15: =IF('Form. Tecnológico'!C155="","",'Form. Tecnológico'!C155) | K15: 10 | L15: =IF('Form. Tecnológico'!C189="","",'Form. Tecnológico'!C189) | M15: 10 | N15: Sim
A16: Eficiência de conversão de radiação (%) | B16: =IF('Form. Tecnológico'!C20="","",'Form. Tecnológico'!C20) -> 22,6% | C16: 10 | D16: =IF('Form. Tecnológico'!C54="","",'Form. Tecnológico'!C54) | E16: 10 | F16: =IF('Form. Tecnológico'!C88="","",'Form. Tecnológico'!C88) | G16: 10 | H16: =IF('Form. Tecnológico'!C122="","",'Form. Tecnológico'!C122) | I16: 10 | J16: =IF('Form. Tecnológico'!C156="","",'Form. Tecnológico'!C156) | K16: 10 | L16: =IF('Form. Tecnológico'!C190="","",'Form. Tecnológico'!C190) | M16: 10 | N16: Sim
A17: Eficiência aos 25 ou 30 anos | B17: =IF('Form. Tecnológico'!C21="","",'Form. Tecnológico'!C21) -> 85,0% (25 anos) | C17: 10 | D17: =IF('Form. Tecnológico'!C55="","",'Form. Tecnológico'!C55) | E17: 10 | F17: =IF('Form. Tecnológico'!C89="","",'Form. Tecnológico'!C89) | G17: 10 | H17: =IF('Form. Tecnológico'!C123="","",'Form. Tecnológico'!C123) | I17: 10 | J17: =IF('Form. Tecnológico'!C157="","",'Form. Tecnológico'!C157) | K17: 10 | L17: =IF('Form. Tecnológico'!C191="","",'Form. Tecnológico'!C191) | M17: 10 | N17: Sim
A18: Garantia contra defeito (anos) | B18: =IF('Form. Tecnológico'!C22="","",'Form. Tecnológico'!C22) -> 12 anos | C18: 10 | D18: =IF('Form. Tecnológico'!C56="","",'Form. Tecnológico'!C56) | E18: 10 | F18: =IF('Form. Tecnológico'!C90="","",'Form. Tecnológico'!C90) | G18: 10 | H18: =IF('Form. Tecnológico'!C124="","",'Form. Tecnológico'!C124) | I18: 10 | J18: =IF('Form. Tecnológico'!C158="","",'Form. Tecnológico'!C158) | K18: 10 | L18: =IF('Form. Tecnológico'!C192="","",'Form. Tecnológico'!C192) | M18: 10 | N18: Sim
A19: Garantia de eficiência (25 ou 30 anos) | B19: =IF('Form. Tecnológico'!C23="","",'Form. Tecnológico'!C23) -> 25 anos | C19: 10 | D19: =IF('Form. Tecnológico'!C57="","",'Form. Tecnológico'!C57) | E19: 10 | F19: =IF('Form. Tecnológico'!C91="","",'Form. Tecnológico'!C91) | G19: 10 | H19: =IF('Form. Tecnológico'!C125="","",'Form. Tecnológico'!C125) | I19: 10 | J19: =IF('Form. Tecnológico'!C159="","",'Form. Tecnológico'!C159) | K19: 10 | L19: =IF('Form. Tecnológico'!C193="","",'Form. Tecnológico'!C193) | M19: 10 | N19: Sim
A20: Inversor de corrente
A21: Marca | B21: =IF('Form. Tecnológico'!C26="","",'Form. Tecnológico'!C26) -> GOODWE | C21: 8 | D21: =IF('Form. Tecnológico'!C60="","",'Form. Tecnológico'!C60) | E21: 10 | F21: =IF('Form. Tecnológico'!C94="","",'Form. Tecnológico'!C94) | G21: 10 | H21: =IF('Form. Tecnológico'!C128="","",'Form. Tecnológico'!C128) | I21: 10 | J21: =IF('Form. Tecnológico'!C162="","",'Form. Tecnológico'!C162) | K21: 4 | L21: =IF('Form. Tecnológico'!C196="","",'Form. Tecnológico'!C196) | M21: 8 | N21: Sim
A22: Modelo | B22: =IF('Form. Tecnológico'!C27="","",'Form. Tecnológico'!C27) -> GW5000 DNS 30 | C22: 8 | D22: =IF('Form. Tecnológico'!C61="","",'Form. Tecnológico'!C61) | E22: 10 | F22: =IF('Form. Tecnológico'!C95="","",'Form. Tecnológico'!C95) | G22: 8 | H22: =IF('Form. Tecnológico'!C129="","",'Form. Tecnológico'!C129) | I22: 10 | J22: =IF('Form. Tecnológico'!C163="","",'Form. Tecnológico'!C163) | K22: 5 | L22: =IF('Form. Tecnológico'!C197="","",'Form. Tecnológico'!C197) | M22: 9 | N22: Sim
A23: Potência (KW = Kilo Watt) | B23: =IF('Form. Tecnológico'!C28="","",'Form. Tecnológico'!C28) -> 5 KW | C23: 8 | D23: =IF('Form. Tecnológico'!C62="","",'Form. Tecnológico'!C62) | E23: 10 | F23: =IF('Form. Tecnológico'!C96="","",'Form. Tecnológico'!C96) | G23: 6 | H23: =IF('Form. Tecnológico'!C130="","",'Form. Tecnológico'!C130) | I23: 10 | J23: =IF('Form. Tecnológico'!C164="","",'Form. Tecnológico'!C164) | K23: 4 | L23: =IF('Form. Tecnológico'!C198="","",'Form. Tecnológico'!C198) | M23: 8 | N23: Sim
A24: Garantia contra defeito (anos) | B24: =IF('Form. Tecnológico'!C29="","",'Form. Tecnológico'!C29) -> 12 anos | C24: 10 | D24: =IF('Form. Tecnológico'!C63="","",'Form. Tecnológico'!C63) | E24: 10 | F24: =IF('Form. Tecnológico'!C97="","",'Form. Tecnológico'!C97) | G24: 7 | H24: =IF('Form. Tecnológico'!C131="","",'Form. Tecnológico'!C131) | I24: 10 | J24: =IF('Form. Tecnológico'!C165="","",'Form. Tecnológico'!C165) | K24: 10 | L24: =IF('Form. Tecnológico'!C199="","",'Form. Tecnológico'!C199) | M24: 10 | N24: Sim
P25: ?
A26: Sobrecarga do inversor | B26: =IF('Form. Tecnológico'!C32="","",'Form. Tecnológico'!C32) -> 1,28 ou 28% | C26: 10 | D26: =IF('Form. Tecnológico'!C66="","",'Form. Tecnológico'!C66) | E26: 10 | F26: =IF('Form. Tecnológico'!C100="","",'Form. Tecnológico'!C100) | G26: 8 | H26: =IF('Form. Tecnológico'!C134="","",'Form. Tecnológico'!C134) | I26: 10 | J26: =IF('Form. Tecnológico'!C168="","",'Form. Tecnológico'!C168) | K26: 10 | L26: =IF('Form. Tecnológico'!C202="","",'Form. Tecnológico'!C202) | M26: 5 | N26: Sim
A28: 🔍 RECLAME AQUI — Reputação dos últimos 12 meses
A29: Distribuidora de sistema solar fotovoltaico | B29: =IF('Form. Tecnológico'!C34="","",'Form. Tecnológico'!C34) -> 8,4/10 - Reputação Ótima | C29: 10 | D29: =IF('Form. Tecnológico'!C68="","",'Form. Tecnológico'!C68) | E29: 10 | F29: =IF('Form. Tecnológico'!C102="","",'Form. Tecnológico'!C102) | G29: 10 | H29: =IF('Form. Tecnológico'!C136="","",'Form. Tecnológico'!C136) | I29: 10 | J29: =IF('Form. Tecnológico'!C170="","",'Form. Tecnológico'!C170) | K29: 10 | L29: =IF('Form. Tecnológico'!C204="","",'Form. Tecnológico'!C204) | M29: 10 | N29: Não
A30: Fabricante de módulo fotovoltaico | B30: =IF('Form. Tecnológico'!C35="","",'Form. Tecnológico'!C35) -> Hanersun - sem avaliação | C30: 10 | D30: =IF('Form. Tecnológico'!C69="","",'Form. Tecnológico'!C69) | E30: 10 | F30: =IF('Form. Tecnológico'!C103="","",'Form. Tecnológico'!C103) | G30: 10 | H30: =IF('Form. Tecnológico'!C137="","",'Form. Tecnológico'!C137) | I30: 10 | J30: =IF('Form. Tecnológico'!C171="","",'Form. Tecnológico'!C171) | K30: 10 | L30: =IF('Form. Tecnológico'!C205="","",'Form. Tecnológico'!C205) | M30: 10 | N30: Não
A31: Fabricante de inversor de corrente | B31: =IF('Form. Tecnológico'!C36="","",'Form. Tecnológico'!C36) -> Growatt - 7,6 - Reputação Boa | C31: 10 | D31: =IF('Form. Tecnológico'!C70="","",'Form. Tecnológico'!C70) | E31: 10 | F31: =IF('Form. Tecnológico'!C104="","",'Form. Tecnológico'!C104) | G31: 10 | H31: =IF('Form. Tecnológico'!C138="","",'Form. Tecnológico'!C138) | I31: 10 | J31: =IF('Form. Tecnológico'!C172="","",'Form. Tecnológico'!C172) | K31: 10 | L31: =IF('Form. Tecnológico'!C206="","",'Form. Tecnológico'!C206) | M31: 10 | N31: Não
A32: Inversor de corrente (sim/não/não sei) | B32: =IF('Form. Tecnológico'!C38="","",'Form. Tecnológico'!C38) -> Sim | C32: 10 | D32: =IF('Form. Tecnológico'!C72="","",'Form. Tecnológico'!C72) | E32: 10 | F32: =IF('Form. Tecnológico'!C106="","",'Form. Tecnológico'!C106) | G32: 7 | H32: =IF('Form. Tecnológico'!C140="","",'Form. Tecnológico'!C140) | I32: 10 | J32: =IF('Form. Tecnológico'!C174="","",'Form. Tecnológico'!C174) | K32: 8 | L32: =IF('Form. Tecnológico'!C208="","",'Form. Tecnológico'!C208) | M32: 5 | N32: Sim
A33: Módulo fotovoltaico (sim/não/não sei) | B33: =IF('Form. Tecnológico'!C39="","",'Form. Tecnológico'!C39) -> Não sei | C33: 10 | D33: =IF('Form. Tecnológico'!C73="","",'Form. Tecnológico'!C73) | E33: 10 | F33: =IF('Form. Tecnológico'!C107="","",'Form. Tecnológico'!C107) | G33: 7 | H33: =IF('Form. Tecnológico'!C141="","",'Form. Tecnológico'!C141) | I33: 10 | J33: =IF('Form. Tecnológico'!C175="","",'Form. Tecnológico'!C175) | K33: 5 | L33: =IF('Form. Tecnológico'!C209="","",'Form. Tecnológico'!C209) | M33: 8 | N33: Sim
A34: Distribuidora de equipamento (sim/não/não sei) | B34: =IF('Form. Tecnológico'!C40="","",'Form. Tecnológico'!C40) -> Sim | C34: 10 | D34: =IF('Form. Tecnológico'!C74="","",'Form. Tecnológico'!C74) | F34: =IF('Form. Tecnológico'!C108="","",'Form. Tecnológico'!C108) | G34: 7 | H34: =IF('Form. Tecnológico'!C142="","",'Form. Tecnológico'!C142) | I34: 10 | J34: =IF('Form. Tecnológico'!C176="","",'Form. Tecnológico'!C176) | K34: 5 | L34: =IF('Form. Tecnológico'!C210="","",'Form. Tecnológico'!C210) | M34: 4 | N34: Sim
A35: TOTAL DA PONTUAÇÃO | C35: =IF($N7="Sim",IFERROR(N(C7),0),0)+IF($N9="Sim",IFERROR(N(C9),0),0)+IF($N10="Sim",IFERROR(N(C10),0),0)+IF($N12="Sim",IFERROR(N(C12),0),0)+IF($N13="Sim",IFERROR(N(C13),0),0)+IF($N14="Sim",IFERROR(N(C14),0),0)+IF($N15="Sim",IFERROR(N(C15),0),0)+IF($N16="Sim",IFERROR(N(C16),0),0)+IF($N17="Sim",IFERROR(N(C17),0),0)+IF($N18="Sim",IFERROR(N(C18),0),0)+IF($N19="Sim",IFERROR(N(C19),0),0)+IF($N21="Sim",IFERROR(N(C21),0),0)+IF($N22="Sim",IFERROR(N(C22),0),0)+IF($N23="Sim",IFERROR(N(C23),0),0)+IF($N24="Sim",IFERROR(N(C24),0),0)+IF($N26="Sim",IFERROR(N(C26),0),0)+IF($N32="Sim",IFERROR(N(C32),0),0)+IF($N33="Sim",IFERROR(N(C33),0),0)+IF($N34="Sim",IFERROR(N(C34),0),0) -> 164 | E35: =IF($N7="Sim",IFERROR(N(E7),0),0)+IF($N9="Sim",IFERROR(N(E9),0),0)+IF($N10="Sim",IFERROR(N(E10),0),0)+IF($N12="Sim",IFERROR(N(E12),0),0)+IF($N13="Sim",IFERROR(N(E13),0),0)+IF($N14="Sim",IFERROR(N(E14),0),0)+IF($N15="Sim",IFERROR(N(E15),0),0)+IF($N16="Sim",IFERROR(N(E16),0),0)+IF($N17="Sim",IFERROR(N(E17),0),0)+IF($N18="Sim",IFERROR(N(E18),0),0)+IF($N19="Sim",IFERROR(N(E19),0),0)+IF($N21="Sim",IFERROR(N(E21),0),0)+IF($N22="Sim",IFERROR(N(E22),0),0)+IF($N23="Sim",IFERROR(N(E23),0),0)+IF($N24="Sim",IFERROR(N(E24),0),0)+IF($N26="Sim",IFERROR(N(E26),0),0)+IF($N32="Sim",IFERROR(N(E32),0),0)+IF($N33="Sim",IFERROR(N(E33),0),0)+IF($N34="Sim",IFERROR(N(E34),0),0) -> 172 | G35: =IF($N7="Sim",IFERROR(N(G7),0),0)+IF($N9="Sim",IFERROR(N(G9),0),0)+IF($N10="Sim",IFERROR(N(G10),0),0)+IF($N12="Sim",IFERROR(N(G12),0),0)+IF($N13="Sim",IFERROR(N(G13),0),0)+IF($N14="Sim",IFERROR(N(G14),0),0)+IF($N15="Sim",IFERROR(N(G15),0),0)+IF($N16="Sim",IFERROR(N(G16),0),0)+IF($N17="Sim",IFERROR(N(G17),0),0)+IF($N18="Sim",IFERROR(N(G18),0),0)+IF($N19="Sim",IFERROR(N(G19),0),0)+IF($N21="Sim",IFERROR(N(G21),0),0)+IF($N22="Sim",IFERROR(N(G22),0),0)+IF($N23="Sim",IFERROR(N(G23),0),0)+IF($N24="Sim",IFERROR(N(G24),0),0)+IF($N26="Sim",IFERROR(N(G26),0),0)+IF($N32="Sim",IFERROR(N(G32),0),0)+IF($N33="Sim",IFERROR(N(G33),0),0)+IF($N34="Sim",IFERROR(N(G34),0),0) -> 152 | I35: =IF($N7="Sim",IFERROR(N(I7),0),0)+IF($N9="Sim",IFERROR(N(I9),0),0)+IF($N10="Sim",IFERROR(N(I10),0),0)+IF($N12="Sim",IFERROR(N(I12),0),0)+IF($N13="Sim",IFERROR(N(I13),0),0)+IF($N14="Sim",IFERROR(N(I14),0),0)+IF($N15="Sim",IFERROR(N(I15),0),0)+IF($N16="Sim",IFERROR(N(I16),0),0)+IF($N17="Sim",IFERROR(N(I17),0),0)+IF($N18="Sim",IFERROR(N(I18),0),0)+IF($N19="Sim",IFERROR(N(I19),0),0)+IF($N21="Sim",IFERROR(N(I21),0),0)+IF($N22="Sim",IFERROR(N(I22),0),0)+IF($N23="Sim",IFERROR(N(I23),0),0)+IF($N24="Sim",IFERROR(N(I24),0),0)+IF($N26="Sim",IFERROR(N(I26),0),0)+IF($N32="Sim",IFERROR(N(I32),0),0)+IF($N33="Sim",IFERROR(N(I33),0),0)+IF($N34="Sim",IFERROR(N(I34),0),0) -> 166 | K35: =IF($N7="Sim",IFERROR(N(K7),0),0)+IF($N9="Sim",IFERROR(N(K9),0),0)+IF($N10="Sim",IFERROR(N(K10),0),0)+IF($N12="Sim",IFERROR(N(K12),0),0)+IF($N13="Sim",IFERROR(N(K13),0),0)+IF($N14="Sim",IFERROR(N(K14),0),0)+IF($N15="Sim",IFERROR(N(K15),0),0)+IF($N16="Sim",IFERROR(N(K16),0),0)+IF($N17="Sim",IFERROR(N(K17),0),0)+IF($N18="Sim",IFERROR(N(K18),0),0)+IF($N19="Sim",IFERROR(N(K19),0),0)+IF($N21="Sim",IFERROR(N(K21),0),0)+IF($N22="Sim",IFERROR(N(K22),0),0)+IF($N23="Sim",IFERROR(N(K23),0),0)+IF($N24="Sim",IFERROR(N(K24),0),0)+IF($N26="Sim",IFERROR(N(K26),0),0)+IF($N32="Sim",IFERROR(N(K32),0),0)+IF($N33="Sim",IFERROR(N(K33),0),0)+IF($N34="Sim",IFERROR(N(K34),0),0) -> 137 | M35: =IF($N7="Sim",IFERROR(N(M7),0),0)+IF($N9="Sim",IFERROR(N(M9),0),0)+IF($N10="Sim",IFERROR(N(M10),0),0)+IF($N12="Sim",IFERROR(N(M12),0),0)+IF($N13="Sim",IFERROR(N(M13),0),0)+IF($N14="Sim",IFERROR(N(M14),0),0)+IF($N15="Sim",IFERROR(N(M15),0),0)+IF($N16="Sim",IFERROR(N(M16),0),0)+IF($N17="Sim",IFERROR(N(M17),0),0)+IF($N18="Sim",IFERROR(N(M18),0),0)+IF($N19="Sim",IFERROR(N(M19),0),0)+IF($N21="Sim",IFERROR(N(M21),0),0)+IF($N22="Sim",IFERROR(N(M22),0),0)+IF($N23="Sim",IFERROR(N(M23),0),0)+IF($N24="Sim",IFERROR(N(M24),0),0)+IF($N26="Sim",IFERROR(N(M26),0),0)+IF($N32="Sim",IFERROR(N(M32),0),0)+IF($N33="Sim",IFERROR(N(M33),0),0)+IF($N34="Sim",IFERROR(N(M34),0),0) -> 161
A36: Itens avaliados (de 19) | C36: =COUNTIF($N$7:$N$34,"Sim") -> 19 | E36: =COUNTIF($N$7:$N$34,"Sim") -> 19 | G36: =COUNTIF($N$7:$N$34,"Sim") -> 19 | I36: =COUNTIF($N$7:$N$34,"Sim") -> 19 | K36: =COUNTIF($N$7:$N$34,"Sim") -> 19 | M36: =COUNTIF($N$7:$N$34,"Sim") -> 19
A37: Pontuação máxima possível | C37: =COUNTIF($N$7:$N$34,"Sim")*10 -> 190 | E37: =COUNTIF($N$7:$N$34,"Sim")*10 -> 190 | G37: =COUNTIF($N$7:$N$34,"Sim")*10 -> 190 | I37: =COUNTIF($N$7:$N$34,"Sim")*10 -> 190 | K37: =COUNTIF($N$7:$N$34,"Sim")*10 -> 190 | M37: =COUNTIF($N$7:$N$34,"Sim")*10 -> 190
A39: © 2026 Buy-Side Soluções. Todos os direitos reservados.
A40: Material protegido pela Lei nº 9.610/98 (Lei de Direitos Autorais). A reprodução, distribuição, modificação ou uso comercial — total ou parcial — é proibida sem autorização expressa do autor.

Sheet Form. Financeiro
B2: 💰 PASSO 3 de 3 — VIABILIDADE ECONÔMICO-FINANCEIRA
B3: 🏠 PREENCHA EM CASA — depois de receber a proposta. Analise números, payback, condições de pagamento com tranquilidade.
B5: ← Anterior: ⚙️ PASSO 2 | C5: 🏆 Ver resultado final →
D7: PULAR PARA EMPRESA ↓
B8: 💰 EMPRESA 1 | D8: 1 | E8: 2 | F8: 3 | G8: 4 | H8: 5 | I8: 6
B9: 📌 Empresa (preenchida automaticamente) | C9: ='Form. Empresa'!C9 -> RENOVA
B10: 📈 SUA CONTA DE ENERGIA
B11: Sem energia solar (R$/mês) | C11: 698.3
B12: Com energia solar (R$/mês) | C12: 141.14
B13: Economia mensal no primeiro ano (R$) | C13: 557.16
B14: Economia no primeiro ano (R$) | C14: 6685.92
B15: Economia acumulada em 25 anos (R$) | C15: 367455.61
B16: 💵 VALOR DE VENDA E INSTALAÇÃO TOTAL DO SISTEMA SOLAR
B17: Preço total (R$) | C17: 17690
B18: 💳 CONDIÇÃO DE PAGAMENTOS
B19: Entrada — no ato da compra (R$) | C19: 9029.95
B20: Entrega de equipamentos (R$) | C20: 4330.02
B21: Instalação — serviço final (R$) | C21: 4330.02
B22: ⏱️ PRAZO DE RETORNO E RENTABILIDADE DO CAPITAL
B23: Payback (simples) — anos e meses | C23: 31 meses
B24: Rentabilidade do capital em 1 ano (%) | C24: 37,80%
B25: ROI (multiplicação por X vezes) | C25: Não informado
B26: 📊 ÍNDICE DE INFLAÇÃO E FATOR DE SIMULTANEIDADE
B27: Índice de inflação de energia estimado 25 anos (% ao ano) | C27: 7% ao ano
B28: Fator de simultaneidade considerado (%) | C28: Não informado
B29: Confiabilidade da viabilidade (alta/média/baixa/não sei) | C29: Baixa
D30: PULAR PARA EMPRESA ↓
B31: 💰 EMPRESA 2 | D31: 1 | E31: 2 | F31: 3 | G31: 4 | H31: 5 | I31: 6
B32: 📌 Empresa (preenchida automaticamente) | C32: ='Form. Empresa'!C29 -> SOLI SOLAR
B33: 📈 SUA CONTA DE ENERGIA
B34: Sem energia solar (R$/mês)
B35: Com energia solar (R$/mês)
B36: Economia mensal no primeiro ano (R$)
B37: Economia no primeiro ano (R$)
B38: Economia acumulada em 25 anos (R$)
B39: 💵 VALOR DE VENDA E INSTALAÇÃO TOTAL DO SISTEMA SOLAR
B40: Preço total (R$) | C40: 16342
B41: 💳 CONDIÇÃO DE PAGAMENTOS
B42: Entrada — no ato da compra (R$)
B43: Entrega de equipamentos (R$)
...

Sheet Viabilidade Financeira
A1: 💰 Tabela 3 — Viabilidade Financeira · Comparativo informativo (sem pontuação)
A2: ← Voltar ao Form. Financeiro | C2: 🏠 Início | E2: 🏆 Ver Pontuação Final →
A4: COMPARATIVO DAS VIABILIDADES ECONÔMICO-FINANCEIRAS DAS PROPOSTAS COMERCIAIS
A5: ITEM | B5: =IF('Form. Empresa'!C9="","1",'Form. Empresa'!C9) -> RENOVA | C5: =IF('Form. Empresa'!C29="","2",'Form. Empresa'!C29) -> SOLI SOLAR | D5: =IF('Form. Empresa'!C49="","3",'Form. Empresa'!C49) -> ENERGIA SGE | E5: =IF('Form. Empresa'!C69="","4",'Form. Empresa'!C69) -> TAP SOLAR | F5: =IF('Form. Empresa'!C89="","5",'Form. Empresa'!C89) -> FOTOVOLTA EXPRESS | G5: =IF('Form. Empresa'!C109="","6",'Form. Empresa'!C109) -> SELF SOLAR
A6: Sua conta com e sem energia solar
A7: Sem energia solar (mês) | B7: =IF('Form. Financeiro'!C11="","",'Form. Financeiro'!C11) -> 698.3 | C7: =IF('Form. Financeiro'!C34="","",'Form. Financeiro'!C34) | D7: =IF('Form. Financeiro'!C57="","",'Form. Financeiro'!C57) | E7: =IF('Form. Financeiro'!C80="","",'Form. Financeiro'!C80) | F7: =IF('Form. Financeiro'!C103="","",'Form. Financeiro'!C103) | G7: =IF('Form. Financeiro'!C126="","",'Form. Financeiro'!C126)
A8: Com energia solar (mês) | B8: =IF('Form. Financeiro'!C12="","",'Form. Financeiro'!C12) -> 141.14 | C8: =IF('Form. Financeiro'!C35="","",'Form. Financeiro'!C35) | D8: =IF('Form. Financeiro'!C58="","",'Form. Financeiro'!C58) | E8: =IF('Form. Financeiro'!C81="","",'Form. Financeiro'!C81) | F8: =IF('Form. Financeiro'!C104="","",'Form. Financeiro'!C104) | G8: =IF('Form. Financeiro'!C127="","",'Form. Financeiro'!C127)
A9: Economia mensal ano 1 | B9: =IF('Form. Financeiro'!C13="","",'Form. Financeiro'!C13) -> 557.16 | C9: =IF('Form. Financeiro'!C36="","",'Form. Financeiro'!C36) | D9: =IF('Form. Financeiro'!C59="","",'Form. Financeiro'!C59) | E9: =IF('Form. Financeiro'!C82="","",'Form. Financeiro'!C82) | F9: =IF('Form. Financeiro'!C105="","",'Form. Financeiro'!C105) | G9: =IF('Form. Financeiro'!C128="","",'Form. Financeiro'!C128)
A10: Economia ano 1 | B10: =IF('Form. Financeiro'!C14="","",'Form. Financeiro'!C14) -> 6685.92 | C10: =IF('Form. Financeiro'!C37="","",'Form. Financeiro'!C37) | D10: =IF('Form. Financeiro'!C60="","",'Form. Financeiro'!C60) | E10: =IF('Form. Financeiro'!C83="","",'Form. Financeiro'!C83) | F10: =IF('Form. Financeiro'!C106="","",'Form. Financeiro'!C106) | G10: =IF('Form. Financeiro'!C129="","",'Form. Financeiro'!C129)
A11: Economia 25/30 anos | B11: =IF('Form. Financeiro'!C15="","",'Form. Financeiro'!C15) -> 367455.61 | C11: =IF('Form. Financeiro'!C38="","",'Form. Financeiro'!C38) | D11: =IF('Form. Financeiro'!C61="","",'Form. Financeiro'!C61) | E11: =IF('Form. Financeiro'!C84="","",'Form. Financeiro'!C84) | F11: =IF('Form. Financeiro'!C107="","",'Form. Financeiro'!C107) | G11: =IF('Form. Financeiro'!C130="","",'Form. Financeiro'!C130)
A12: Valor de venda e instalação do sistema solar
A13: Valor de investimento | B13: =IF('Form. Financeiro'!C17="","",'Form. Financeiro'!C17) -> 17690 | C13: =IF('Form. Financeiro'!C40="","",'Form. Financeiro'!C40) -> 16342 | D13: =IF('Form. Financeiro'!C63="","",'Form. Financeiro'!C63) -> 15900 | E13: =IF('Form. Financeiro'!C86="","",'Form. Financeiro'!C86) -> 14500 | F13: =IF('Form. Financeiro'!C109="","",'Form. Financeiro'!C109) -> 17326.75 | G13: =IF('Form. Financeiro'!C132="","",'Form. Financeiro'!C132) -> 16500
A14: Condição de pagamentos
A15: Entrada (R$) | B15: =IF('Form. Financeiro'!C19="","",'Form. Financeiro'!C19) -> 9029.95 | C15: =IF('Form. Financeiro'!C42="","",'Form. Financeiro'!C42) | D15: =IF('Form. Financeiro'!C65="","",'Form. Financeiro'!C65) | E15: =IF('Form. Financeiro'!C88="","",'Form. Financeiro'!C88) | F15: =IF('Form. Financeiro'!C111="","",'Form. Financeiro'!C111) | G15: =IF('Form. Financeiro'!C134="","",'Form. Financeiro'!C134)
A16: Entrega equipamento (R$) | B16: =IF('Form. Financeiro'!C20="","",'Form. Financeiro'!C20) -> 4330.02 | C16: =IF('Form. Financeiro'!C43="","",'Form. Financeiro'!C43) | D16: =IF('Form. Financeiro'!C66="","",'Form. Financeiro'!C66) | E16: =IF('Form. Financeiro'!C89="","",'Form. Financeiro'!C89) | F16: =IF('Form. Financeiro'!C112="","",'Form. Financeiro'!C112) | G16: =IF('Form. Financeiro'!C135="","",'Form. Financeiro'!C135)
A17: Final de serviços (R$) | B17: =IF('Form. Financeiro'!C21="","",'Form. Financeiro'!C21) -> 4330.02 | C17: =IF('Form. Financeiro'!C44="","",'Form. Financeiro'!C44) | D17: =IF('Form. Financeiro'!C67="","",'Form. Financeiro'!C67) | E17: =IF('Form. Financeiro'!C90="","",'Form. Financeiro'!C90) | F17: =IF('Form. Financeiro'!C113="","",'Form. Financeiro'!C113) | G17: =IF('Form. Financeiro'!C136="","",'Form. Financeiro'!C136)
A18: Prazo de retorno e rentabilidade do capital
A19: Prazo de retorno (simples) | B19: =IF('Form. Financeiro'!C23="","",'Form. Financeiro'!C23) -> 31 meses | C19: =IF('Form. Financeiro'!C46="","",'Form. Financeiro'!C46) | D19: =IF('Form. Financeiro'!C69="","",'Form. Financeiro'!C69) | E19: =IF('Form. Financeiro'!C92="","",'Form. Financeiro'!C92) | F19: =IF('Form. Financeiro'!C115="","",'Form. Financeiro'!C115) | G19: =IF('Form. Financeiro'!C138="","",'Form. Financeiro'!C138)
A20: Rentabilidade do capital anual | B20: =IF('Form. Financeiro'!C24="","",'Form. Financeiro'!C24) -> 37,80% | C20: =IF('Form. Financeiro'!C47="","",'Form. Financeiro'!C47) | D20: =IF('Form. Financeiro'!C70="","",'Form. Financeiro'!C70) | E20: =IF('Form. Financeiro'!C93="","",'Form. Financeiro'!C93) | F20: =IF('Form. Financeiro'!C116="","",'Form. Financeiro'!C116) | G20: =IF('Form. Financeiro'!C139="","",'Form. Financeiro'!C139)
A21: Rentabilidade do capital mensal | B21: 3,15% ao mês
A22: ROI | B22: =IF('Form. Financeiro'!C25="","",'Form. Financeiro'!C25) -> Não informado | C22: =IF('Form. Financeiro'!C48="","",'Form. Financeiro'!C48) | D22: =IF('Form. Financeiro'!C71="","",'Form. Financeiro'!C71) | E22: =IF('Form. Financeiro'!C94="","",'Form. Financeiro'!C94) | F22: =IF('Form. Financeiro'!C117="","",'Form. Financeiro'!C117) | G22: =IF('Form. Financeiro'!C140="","",'Form. Financeiro'!C140)
A23: Indicadores econômicos e técnicos considerados nas análises de viabilidades
A24: Fator de simultaneidade | B24: =IF('Form. Financeiro'!C28="","",'Form. Financeiro'!C28) -> Não informado | C24: =IF('Form. Financeiro'!C51="","",'Form. Financeiro'!C51) | D24: =IF('Form. Financeiro'!C74="","",'Form. Financeiro'!C74) | E24: =IF('Form. Financeiro'!C97="","",'Form. Financeiro'!C97) | F24: =IF('Form. Financeiro'!C120="","",'Form. Financeiro'!C120) | G24: =IF('Form. Financeiro'!C143="","",'Form. Financeiro'!C143)
A25: Inflação anual de energia (% ano) | B25: =IF('Form. Financeiro'!C27="","",'Form. Financeiro'!C27) -> 7% ao ano | C25: =IF('Form. Financeiro'!C50="","",'Form. Financeiro'!C50) | D25: =IF('Form. Financeiro'!C73="","",'Form. Financeiro'!C73) | E25: =IF('Form. Financeiro'!C96="","",'Form. Financeiro'!C96) | F25: =IF('Form. Financeiro'!C119="","",'Form. Financeiro'!C119) | G25: =IF('Form. Financeiro'!C142="","",'Form. Financeiro'!C142)
A26: Confiabilidade da viabilidade (alta/média/baixa/não sei) | B26: =IF('Form. Financeiro'!C29="","",'Form. Financeiro'!C29) -> Baixa | C26: =IF('Form. Financeiro'!C52="","",'Form. Financeiro'!C52) | D26: =IF('Form. Financeiro'!C75="","",'Form. Financeiro'!C75) | E26: =IF('Form. Financeiro'!C98="","",'Form. Financeiro'!C98) | F26: =IF('Form. Financeiro'!C121="","",'Form. Financeiro'!C121) | G26: =IF('Form. Financeiro'!C144="","",'Form. Financeiro'!C144)
A28: ⚠️ Observações sobre o quadro de viabilidade econômico-financeira
A29: No terceiro quadro, você notou que não atribuímos pontuação para a análise de viabilidade econômico-financeira. Isso acontece porque muitas vezes os valores apresentados pelas empresas variam muito e podem não ser confiáveis.
A30: É crucial entender que análises como essa, focadas em sistemas fotovoltaicos, podem ser facilmente manipuladas. Isso ocorre quando variáveis importantes como o índice de reajuste da energia, o fator de simultaneidade e as previsões de geração EXAGERADAS levam a valores artificiais. Essa prática pode levar a resultados distorcidos, prejudicando a qualidade da análise e fazendo com que você tome decisões totalmente erradas.
A31: De forma geral: maiores os índices de reajuste da energia, de simultaneidade e de geração, menor o prazo de retorno — podendo levar a resultado enganador!
A32: No entanto, esse quadro tem como objetivo principal permitir uma análise comparativa entre os valores apresentados, possibilitando que se tirem conclusões informadas.
A34: © 2026 Buy-Side Soluções. Todos os direitos reservados.
A35: Material protegido pela Lei nº 9.610/98 (Lei de Direitos Autorais). A reprodução, distribuição, modificação ou uso comercial — total ou parcial — é proibida sem autorização expressa do autor.

Sheet Pontuação Geral
A1: 🏆 RESULTADO FINAL — Pontuação Geral e Finalistas
A2: 🏠 Início | C2: 📊 Ver Avaliação Empresas | E2: 📊 Ver Avaliação Tecnológica
A4: 📊 SEÇÃO 1 — Pontuação das Propostas
A5: ITEM | B5: =IF('Form. Empresa'!C9="","1",'Form. Empresa'!C9) -> RENOVA | C5: =IF('Form. Empresa'!C29="","2",'Form. Empresa'!C29) -> SOLI SOLAR | D5: =IF('Form. Empresa'!C49="","3",'Form. Empresa'!C49) -> ENERGIA SGE | E5: =IF('Form. Empresa'!C69="","4",'Form. Empresa'!C69) -> TAP SOLAR | F5: =IF('Form. Empresa'!C89="","5",'Form. Empresa'!C89) -> FOTOVOLTA EXPRESS | G5: =IF('Form. Empresa'!C109="","6",'Form. Empresa'!C109) -> SELF SOLAR
A6: Investimentos | B6: ='Viabilidade Financeira'!B13 -> 17690 | C6: ='Viabilidade Financeira'!C13 -> 16342 | D6: ='Viabilidade Financeira'!D13 -> 15900 | E6: ='Viabilidade Financeira'!E13 -> 14500 | F6: ='Viabilidade Financeira'!F13 -> 17326.75 | G6: ='Viabilidade Financeira'!G13 -> 16500
A7: Empresas (pontos) | B7: ='Avaliação Empresas'!C24 -> 81 | C7: ='Avaliação Empresas'!E24 -> 92 | D7: ='Avaliação Empresas'!G24 -> 26 | E7: ='Avaliação Empresas'!I24 -> 46 | F7: ='Avaliação Empresas'!K24 -> 72 | G7: ='Avaliação Empresas'!M24 -> 41
A8: Nota sobre 10 | B8: =IF('Avaliação Empresas'!C26=0,0,ROUND(B7/'Avaliação Empresas'!C26*10,2)) -> 6.23 | C8: =IF('Avaliação Empresas'!E26=0,0,ROUND(C7/'Avaliação Empresas'!E26*10,2)) -> 7.08 | D8: =IF('Avaliação Empresas'!G26=0,0,ROUND(D7/'Avaliação Empresas'!G26*10,2)) -> 2 | E8: =IF('Avaliação Empresas'!I26=0,0,ROUND(E7/'Avaliação Empresas'!I26*10,2)) -> 3.54 | F8: =IF('Avaliação Empresas'!K26=0,0,ROUND(F7/'Avaliação Empresas'!K26*10,2)) -> 5.54 | G8: =IF('Avaliação Empresas'!M26=0,0,ROUND(G7/'Avaliação Empresas'!M26*10,2)) -> 3.15
A9: Tecnologias (pontos) | B9: ='Avaliação Tecnológica'!C35 -> 164 | C9: ='Avaliação Tecnológica'!E35 -> 172 | D9: ='Avaliação Tecnológica'!G35 -> 152 | E9: ='Avaliação Tecnológica'!I35 -> 166 | F9: ='Avaliação Tecnológica'!K35 -> 137 | G9: ='Avaliação Tecnológica'!M35 -> 161
A10: Nota sobre 10 | B10: =IF('Avaliação Tecnológica'!C37=0,0,ROUND(B9/'Avaliação Tecnológica'!C37*10,2)) -> 8.63 | C10: =IF('Avaliação Tecnológica'!E37=0,0,ROUND(C9/'Avaliação Tecnológica'!E37*10,2)) -> 9.05 | D10: =IF('Avaliação Tecnológica'!G37=0,0,ROUND(D9/'Avaliação Tecnológica'!G37*10,2)) -> 8 | E10: =IF('Avaliação Tecnológica'!I37=0,0,ROUND(E9/'Avaliação Tecnológica'!I37*10,2)) -> 8.74 | F10: =IF('Avaliação Tecnológica'!K37=0,0,ROUND(F9/'Avaliação Tecnológica'!K37*10,2)) -> 7.21 | G10: =IF('Avaliação Tecnológica'!M37=0,0,ROUND(G9/'Avaliação Tecnológica'!M37*10,2)) -> 8.47
A11: Total (pontos) | B11: =B7+B9 -> 245 | C11: =C7+C9 -> 264 | D11: =D7+D9 -> 178 | E11: =E7+E9 -> 212 | F11: =F7+F9 -> 209 | G11: =G7+G9 -> 202
A12: Nota sobre 10 | B12: =IF(('Avaliação Empresas'!C26+'Avaliação Tecnológica'!C37)=0,0,ROUND(B11/('Avaliação Empresas'!C26+'Avaliação Tecnológica'!C37)*10,2)) -> 7.66 | C12: =IF(('Avaliação Empresas'!E26+'Avaliação Tecnológica'!E37)=0,0,ROUND(C11/('Avaliação Empresas'!E26+'Avaliação Tecnológica'!E37)*10,2)) -> 8.25 | D12: =IF(('Avaliação Empresas'!G26+'Avaliação Tecnológica'!G37)=0,0,ROUND(D11/('Avaliação Empresas'!G26+'Avaliação Tecnológica'!G37)*10,2)) -> 5.56 | E12: =IF(('Avaliação Empresas'!I26+'Avaliação Tecnológica'!I37)=0,0,ROUND(E11/('Avaliação Empresas'!I26+'Avaliação Tecnológica'!I37)*10,2)) -> 6.63 | F12: =IF(('Avaliação Empresas'!K26+'Avaliação Tecnológica'!K37)=0,0,ROUND(F11/('Avaliação Empresas'!K26+'Avaliação Tecnológica'!K37)*10,2)) -> 6.53 | G12: =IF(('Avaliação Empresas'!M26+'Avaliação Tecnológica'!M37)=0,0,ROUND(G11/('Avaliação Empresas'!M26+'Avaliação Tecnológica'!M37)*10,2)) -> 6.31
A14: ✅ DECISÃO DO COMPRADOR | B14: 🏆 Finalista | C14: 🏆 Finalista | D14: ❌ Descartada | E14: ❌ Descartada | F14: ❌ Descartada | G14: ❌ Descartada
A15: =IF(COUNTIF(B14:G14,"*Finalista*")=2,"✅ 2 finalistas selecionados",IF(COUNTIF(B14:G14,"*Finalista*")<2,"⚠️ Faltam finalistas — escolha exatamente 2 na linha acima","⚠️ Finalistas em excesso — selecione apenas 2 na linha acima")) -> ✅ 2 finalistas selecionados
A17: 🎯 SEÇÃO 2 — Escala de Risco
A18: ESCALA DE RISCO
A20: Avalie sua proposta de 0 a 10 pontos
A26: 📌 SEÇÃO 3 — Observações Importantes
A29: • As duas propostas finalistas, selecionadas para a última rodada de negociações, apresentam as seguintes características:
A30: ○ Apesar de estarem entre as propostas com dois dos três maiores preços, foram consideradas as melhores no conjunto de critérios avaliados.
A31: ○ Obtiveram as maiores pontuações, refletindo maior experiência, competência e estrutura organizacional no setor de energia solar.
A33: • Considerações sobre preços e riscos ocultos:
A34: ○ O menor preço pode, em alguns casos, ocultar riscos significativos, como:
A35: ▪ A utilização de tecnologias de marcas pouco conhecidas no mercado brasileiro.
A36: ▪ Equipamentos de qualidade inferior ou de segunda linha.
A37: ▪ Indícios de fragilidade estrutural ou organizacional por parte da empresa fornecedora.
... A47: Material protegido pela Lei nº 9.610/98 (Lei de Direitos Autorais). A reprodução, distribuição, modificação ou uso comercial — total ou parcial — é proibida sem autorização expressa do autor.

Sheet Critérios de Pontuação
A1: CRITÉRIOS DE PONTUAÇÃO — ESCALA 1 A 10 POR ITEM
A2: Regra geral: cada item recebe nota de 1 a 10. Itens não avaliados podem ser desligados na coluna "Avaliar?" da tabela comparativa — o denominador da nota recalcula sozinho.
A3: Rubrica padrão sugerida: 10 = excelente · 8-9 = muito bom · 6-7 = bom · 4-5 = regular · 2-3 = fraco · 1 = ruim | B3: Pontos Máx | C3: Critério de pontuação
B4: 10 | C4: 1 pt por ano de atuação, máx 10
A5: AVALIAÇÃO EMPRESAS — 13 itens | B5: 5 | C5: 5 se >10 anos | 3 se 5-10 anos | 1 se <5 anos
A6: Item | B6: Como pontuar (1 a 10) | C6: Observação
A7: Atuação no ramo solar (anos) | B7: 10 se ≥10 anos · 7 se 5-9 · 4 se 2-4 · 1 se <2 | C7: Tempo de mercado no segmento
A8: Ano de abertura da empresa | B8: 10 se ≥15 anos de existência · 7 se 8-14 · 4 se 3-7 · 1 se <3 | C8: Maturidade institucional
A9: Registro CREA do engenheiro | B9: 10 se Sim · 1 se Não | C9: Item crítico (legal)
A10: Ano de colação do engenheiro | B10: 10 se ≥10 anos formado · 7 se 5-9 · 4 se 2-4 · 1 se <2 | C10: Experiência do responsável técnico
A11: Quantidade de SFV instalados | B11: 10 se >100 · 7 se 50-100 · 4 se 10-49 · 1 se <10 | C11: Histórico de execução
A12: Instalação por funcionário próprio | B12: 10 se Sim · 5 se Terceirizado conhecido · 1 se Não | C12: Controle de qualidade da mão de obra
A13: Prazo de instalação (dias) | B13: 10 se ≤30d · 7 se 31-45 · 4 se 46-60 · 1 se >60 | C13: Agilidade prometida
A14: Garantia projeto/execução (anos) | B14: 10 se ≥5 anos · 7 se 3-4 · 4 se 1-2 · 1 se <1 | C14: Compromisso pós-venda
A15: Serviço de manutenção/assistência | B15: 10 se Sim · 1 se Não | C15: Disponibilidade de suporte
A16: Prazo de assistência técnica (dias) | B16: 10 se ≤3d · 7 se 4-7 · 4 se 8-15 · 1 se >15 | C16: Velocidade de atendimento
A17: Memorial descritivo e diagrama unifilar | B17: 10 se Sim · 1 se Não | C17: Documentação técnica entregue
A18: Empatia/confiança com o vendedor | B18: Subjetivo: 1 a 10 segundo percepção do comprador | C18: Relacionamento comercial
A19: Reclame Aqui — reputação
B20: Pontos Máx | C20: Critério de pontuação
A21: AVALIAÇÃO TECNOLÓGICA — 19 itens | B21: 10 | C21: Pontuação proporcional ao kWp ofertado vs necessidade
A22: Item | B22: Como pontuar (1 a 10) | C22: Observação
A23: Potência do sistema (kWp) | B23: Proporcional à necessidade — 10 se dimensionamento ideal · menor se sub/superdimensionado | C23: Adequação ao consumo
A24: Geração mensal estimada (kWh) | B24: 10 se cobre 100% do consumo · 7 se 80-99% · 4 se 60-79% · 1 se <60% | C24: Atende a fatura mensal?
A25: Geração anual estimada (kWh) | B25: Mesma lógica do mensal, base anual | C25: Atende consumo anual?
A26: Módulo — Marca | B26: 10 se Tier 1 reconhecida · 5 se Tier 2 · 1 se desconhecida | C26: Confiabilidade do fabricante
A27: Módulo — Modelo | B27: 10 se modelo atual de linha · 4 se descontinuado/antigo | C27: Disponibilidade de reposição
A28: Módulo — Potência (W) | B28: 10 se ≥550W · 7 se 450-549 · 4 se 350-449 · 1 se <350 | C28: Quanto maior, menos módulos no telhado
A29: Módulo — Peso (kg) | B29: 10 se ≤25kg · 7 se 26-30 · 4 se 31-35 · 1 se >35 | C29: Carga no telhado
A30: Eficiência (%) | B30: 10 se ≥22% · 7 se 20-21,9% · 4 se 18-19,9% · 1 se <18% | C30: Conversão sol→energia
A31: Eficiência aos 25/30 anos | B31: 10 se ≥85% · 7 se 80-84% · 4 se 75-79% · 1 se <75% | C31: Durabilidade da geração
A32: Garantia contra defeito do módulo | B32: 10 se ≥12 anos · 7 se 8-11 · 4 se 5-7 · 1 se <5 | C32: Cobertura de fábrica
A33: Garantia de eficiência (anos) | B33: 10 se 30 anos · 7 se 25 · 4 se <25 | C33: Linear performance warranty
... A40: Reclame Aqui — Fabricante módulo | B40: 10 se Ótimo · 7 se Bom · 4 se Regular · 1 se Ruim | C40: Reputação últimos 12 meses
A42: © 2026 Solar Buy-Side. Todos os direitos reservados.
A43: Material protegido pela Lei nº 9.610/98 (Lei de Direitos Autorais). A reprodução, distribuição, modificação ou uso comercial — total ou parcial — é proibida sem autorização expressa do autor.
